Workbook

Sheet Price List
A1: NIKSANG — MASTER PRICE LIST (up to 300 products)
A2: Enter all products & services here. Yellow cells = editable inputs. GST must be 5, 12 or 18.
A3: # | B3: Product / Service Name | C3: Category | D3: Unit | E3: Retail Price | F3: Trade Price | G3: Wholesale Price | H3: GST Rate (%) | I3: Material/Size Option | J3: Notes
A4: 1 | B4: T Yellow Panel | C4: Materials | D4: Sft | E4: 127.11352 | F4: 114.40217 | G4: 111.8599 | H4: 5 | I4: Standard
A5: 2 | B5: T Yellow Panel | C5: Materials | D5: Sft | E5: 127.11352 | F5: 114.40217 | G5: 111.8599 | H5: 5 | I5: Large
A6: 3 | B6: C Gold Panel | C6: Materials | D6: Sft | E6: 98.1981 | F6: 88.37829 | G6: 86.414328 | H6: 5
A7: 4 | B7: C Gold Interlock Panel | C7: Materials | D7: Sft | E7: 98.1981 | F7: 88.37829 | G7: 86.414328 | H7: 5
A8: 5 | B8: M Green Panel | C8: Materials | D8: Sft | E8: 136.85017 | F8: 123.16516 | G8: 120.42815 | H8: 5 | I8: Grade A
A9: 6 | B9: M Rustic Green Panel | C9: Materials | D9: Sft | E9: 136.3131 | F9: 122.68179 | G9: 119.95553 | H9: 5
A10: 7 | B10: Autumn Panel | C10: Materials | D10: Sft | E10: 98.1981 | F10: 88.37829 | G10: 86.414328 | H10: 5
A11: 8 | B11: Autumn Panel | C11: Materials | D11: Sft | E11: 99.27225 | F11: 89.345025 | G11: 87.35958 | H11: 5
A12: 9 | B12: A Black Panel | C12: Materials | D12: Sft | E12: 98.1981 | F12: 88.37829 | G12: 86.414328 | H12: 5
A13: 10 | B13: A Black Panel | C13: Materials | D13: Sft | E13: 100.3464 | F13: 90.31176 | G13: 88.304832 | H13: 5
A14: 11 | B14: A Black Panel | C14: Materials | D14: Sft | E14: 100.3464 | F14: 90.31176 | G14: 88.304832 | H14: 5
A15: 12 | B15: Multi Pink Panel | C15: Materials | D15: Sft | E15: 99.27225 | F15: 89.345025 | G15: 87.35958 | H15: 5
A16: 13 | B16: Black Butching Panel | C16: Materials | D16: Sft | E16: 182.77875 | F16: 164.50088 | G16: 160.8453 | H16: 5
A17: 14 | B17: Black Rustic Panel | C17: Materials | D17: Sft | E17: 96.586875 | F17: 86.928188 | G17: 84.99645 | H17: 5
A18: 15 | B18: N Green Panel | C18: Materials | D18: Sft | E18: 101.6631 | F18: 91.49679 | G18: 89.463528 | H18: 5
A19: 16 | B19: Gold Butching Panel | C19: Materials | D19: Sft | E19: 156.79125 | F19: 141.11212 | G19: 137.9763 | H19: 5
A20: 17 | B20: Bamboo 3D Panel | C20: Materials | D20: Sft | E20: 259.45227 | F20: 233.50704 | G20: 228.318 | H20: 5
... A85: 82 | B85: Rock & Tumble Agra | C85: Materials | D85: Sft | E85: 143.48565 | F85: 129.13709 | G85: 126.26737 | H85: 18
A86: 83
A87: 84 | B87: Hexagon Autumn Pcs Panel | C87: Materials | D87: Sft | E87: 80.0415 | F87: 72.03735 | G87: 70.43652 | H87: 5
A88: 85 | B88: Hexagon Black Rustic Pcs Panel | C88: Materials | D88: Sft | E88: 80.0415 | F88: 72.03735 | G88: 70.43652 | H88: 5
A89: 86 | B89: Rustic Black Crazy Pattern(A) | C89: Materials | D89: Sft | E89: 333.1251 | F89: 299.81259 | G89: 293.15009 | H89: 5
A90: 87 | B90: Rustic Black Crazy Pattern(B) | C90: Materials | D90: Sft | E90: 333.1251 | F90: 299.81259 | G90: 293.15009 | H90: 5
A91: 88 | B91: Rustic Black Crazy Pattern | C91: Materials | D91: Sft | E91: 333.1251 | F91: 299.81259 | G91: 293.15009 | H91: 5
A92: 89 | B92: Rustic Black Crazy Pattern | C92: Materials | D92: Sft | E92: 333.1251 | F92: 299.81259 | G92: 293.15009 | H92: 5
A93: 90 | B93: T Yellow Crazy Pattern | C93: Materials | D93: Sft | E93: 476.4375 | F93: 428.79375 | G93: 419.265 | H93: 5
A94: 91 | B94: Gold Honed & Bevelled | C94: Materials | D94: Sft | E94: 73.371375 | F94: 66.034238 | G94: 64.56681 | H94: 5
A95: 92 | B95: Gold Honed & Bevelled | C95: Materials | D95: Sft | E95: 129.96637 | F95: 116.96974 | G95: 114.37041 | H95: 5
A96: 93 | B96: Rustic Black Honed & Bevelled | C96: Materials | D96: Sft | E96: 73.371375 | F96: 66.034238 | G96: 64.56681 | H96: 5
A97: 94 | B97: Rustic Black | C97: Materials | D97: Sft | E97: 129.96637 | F97: 116.96974 | G97: 114.37041 | H97: 5
A98: 95
A99: 96
A100: 97
A101: 98
A102: 99
A103: 100
A104: 101
...

Sheet Quote Builder
A1: NIKSANG — QUOTE BUILDER
A2: Fill yellow cells. Type the exact product name from the Price List. Prices & GST auto-fill.
A3: CUSTOMER DETAILS
B4: Quote Number:
A5: Quote Date: | B5: =TODAY() -> 46087
A6: Valid Until: | B6: =TODAY()+30 -> 46117
A7: Customer Name: | B7: Saravana
A8: Customer Type: | B8: Retail
A9: Customer Email:
A10: Customer Phone:
A11: Overall Discount %: | B11: 0
A13: QUOTE LINE ITEMS
A14: # | B14: Product / Service Name | C14: Category | D14: Unit | E14: Qty | F14: Unit Price (excl. GST) | G14: Line Disc % | H14: Amount (excl. GST) | I14: GST % | J14: GST Amt | K14: Total (incl. GST)
A15: 1 | B15: black butching panel | C15: =IF(B15="","",IFERROR(VLOOKUP(B15,'Price List'!$B$4:$J$303,2,0),"- not found -")) -> Materials | D15: =IF(B15="","",IFERROR(VLOOKUP(B15,'Price List'!$B$4:$J$303,3,0),"")) -> Sft | E15: 100 | F15: =IF(B15="","",IF($B$8="Retail",IFERROR(VLOOKUP(B15,'Price List'!$B$4:$J$303,4,0),0),IF($B$8="Trade",IFERROR(VLOOKUP(B15,'Price List'!$B$4:$J$303,5,0),0),IFERROR(VLOOKUP(B15,'Price List'!$B$4:$J$303,6,0),0)))) -> 182.77875 | G15: 0 | H15: =IF(B15="","",IF(E15="","",ROUND(F15*(1-G15/100)*E15,2))) -> 18277.88 | I15: =IF(B15="","",IFERROR(VLOOKUP(B15,'Price List'!$B$4:$J$303,7,0),0)) -> 5 | J15: =IF(H15="","",ROUND(H15*I15/100,2)) -> 913.89 | K15: =IF(H15="","",H15+J15) -> 19191.77
A16: 2 | C16: =IF(B16="","",IFERROR(VLOOKUP(B16,'Price List'!$B$4:$J$303,2,0),"- not found -")) | D16: =IF(B16="","",IFERROR(VLOOKUP(B16,'Price List'!$B$4:$J$303,3,0),"")) | F16: =IF(B16="","",IF($B$8="Retail",IFERROR(VLOOKUP(B16,'Price List'!$B$4:$J$303,4,0),0),IF($B$8="Trade",IFERROR(VLOOKUP(B16,'Price List'!$B$4:$J$303,5,0),0),IFERROR(VLOOKUP(B16,'Price List'!$B$4:$J$303,6,0),0)))) | G16: 0 | H16: =IF(B16="","",IF(E16="","",ROUND(F16*(1-G16/100)*E16,2))) | I16: =IF(B16="","",IFERROR(VLOOKUP(B16,'Price List'!$B$4:$J$303,7,0),0)) | J16: =IF(H16="","",ROUND(H16*I16/100,2)) | K16: =IF(H16="","",H16+J16)
A17: 3 | C17: =IF(B17="","",IFERROR(VLOOKUP(B17,'Price List'!$B$4:$J$303,2,0),"- not found -")) | D17: =IF(B17="","",IFERROR(VLOOKUP(B17,'Price List'!$B$4:$J$303,3,0),"")) | F17: =IF(B17="","",IF($B$8="Retail",IFERROR(VLOOKUP(B17,'Price List'!$B$4:$J$303,4,0),0),IF($B$8="Trade",IFERROR(VLOOKUP(B17,'Price List'!$B$4:$J$303,5,0),0),IFERROR(VLOOKUP(B17,'Price List'!$B$4:$J$303,6,0),0)))) | G17: 0 | H17: =IF(B17="","",IF(E17="","",ROUND(F17*(1-G17/100)*E17,2))) | I17: =IF(B17="","",IFERROR(VLOOKUP(B17,'Price List'!$B$4:$J$303,7,0),0)) | J17: =IF(H17="","",ROUND(H17*I17/100,2)) | K17: =IF(H17="","",H17+J17)
A18: 4 | C18: =IF(B18="","",IFERROR(VLOOKUP(B18,'Price List'!$B$4:$J$303,2,0),"- not found -")) | D18: =IF(B18="","",IFERROR(VLOOKUP(B18,'Price List'!$B$4:$J$303,3,0),"")) | F18: =IF(B18="","",IF($B$8="Retail",IFERROR(VLOOKUP(B18,'Price List'!$B$4:$J$303,4,0),0),IF($B$8="Trade",IFERROR(VLOOKUP(B18,'Price List'!$B$4:$J$303,5,0),0),IFERROR(VLOOKUP(B18,'Price List'!$B$4:$J$303,6,0),0)))) | G18: 0 | H18: =IF(B18="","",IF(E18="","",ROUND(F18*(1-G18/100)*E18,2))) | I18: =IF(B18="","",IFERROR(VLOOKUP(B18,'Price List'!$B$4:$J$303,7,0),0)) | J18: =IF(H18="","",ROUND(H18*I18/100,2)) | K18: =IF(H18="","",H18+J18)
A19: 5 | C19: =IF(B19="","",IFERROR(VLOOKUP(B19,'Price List'!$B$4:$J$303,2,0),"- not found -")) | D19: =IF(B19="","",IFERROR(VLOOKUP(B19,'Price List'!$B$4:$J$303,3,0),"")) | F19: =IF(B19="","",IF($B$8="Retail",IFERROR(VLOOKUP(B19,'Price List'!$B$4:$J$303,4,0),0),IF($B$8="Trade",IFERROR(VLOOKUP(B19,'Price List'!$B$4:$J$303,5,0),0),IFERROR(VLOOKUP(B19,'Price List'!$B$4:$J$303,6,0),0)))) | G19: 0 | H19: =IF(B19="","",IF(E19="","",ROUND(F19*(1-G19/100)*E19,2))) | I19: =IF(B19="","",IFERROR(VLOOKUP(B19,'Price List'!$B$4:$J$303,7,0),0)) | J19: =IF(H19="","",ROUND(H19*I19/100,2)) | K19: =IF(H19="","",H19+J19)
A20: 6 | C20: =IF(B20="","",IFERROR(VLOOKUP(B20,'Price List'!$B$4:$J$303,2,0),"- not found -")) | D20: =IF(B20="","",IFERROR(VLOOKUP(B20,'Price List'!$B$4:$J$303,3,0),"")) | F20: =IF(B20="","",IF($B$8="Retail",IFERROR(VLOOKUP(B20,'Price List'!$B$4:$J$303,4,0),0),IF($B$8="Trade",IFERROR(VLOOKUP(B20,'Price List'!$B$4:$J$303,5,0),0),IFERROR(VLOOKUP(B20,'Price List'!$B$4:$J$303,6,0),0)))) | G20: 0 | H20: =IF(B20="","",IF(E20="","",ROUND(F20*(1-G20/100)*E20,2))) | I20: =IF(B20="","",IFERROR(VLOOKUP(B20,'Price List'!$B$4:$J$303,7,0),0)) | J20: =IF(H20="","",ROUND(H20*I20/100,2)) | K20: =IF(H20="","",H20+J20)
A21: 7 | C21: =IF(B21="","",IFERROR(VLOOKUP(B21,'Price List'!$B$4:$J$303,2,0),"- not found -")) | D21: =IF(B21="","",IFERROR(VLOOKUP(B21,'Price List'!$B$4:$J$303,3,0),"")) | F21: =IF(B21="","",IF($B$8="Retail",IFERROR(VLOOKUP(B21,'Price List'!$B$4:$J$303,4,0),0),IF($B$8="Trade",IFERROR(VLOOKUP(B21,'Price List'!$B$4:$J$303,5,0),0),IFERROR(VLOOKUP(B21,'Price List'!$B$4:$J$303,6,0),0)))) | G21: 0 | H21: =IF(B21="","",IF(E21="","",ROUND(F21*(1-G21/100)*E21,2))) | I21: =IF(B21="","",IFERROR(VLOOKUP(B21,'Price List'!$B$4:$J$303,7,0),0)) | J21: =IF(H21="","",ROUND(H21*I21/100,2)) | K21: =IF(H21="","",H21+J21)
A22: 8 | C22: =IF(B22="","",IFERROR(VLOOKUP(B22,'Price List'!$B$4:$J$303,2,0),"- not found -")) | D22: =IF(B22="","",IFERROR(VLOOKUP(B22,'Price List'!$B$4:$J$303,3,0),"")) | F22: =IF(B22="","",IF($B$8="Retail",IFERROR(VLOOKUP(B22,'Price List'!$B$4:$J$303,4,0),0),IF($B$8="Trade",IFERROR(VLOOKUP(B22,'Price List'!$B$4:$J$303,5,0),0),IFERROR(VLOOKUP(B22,'Price List'!$B$4:$J$303,6,0),0)))) | G22: 0 | H22: =IF(B22="","",IF(E22="","",ROUND(F22*(1-G22/100)*E22,2))) | I22: =IF(B22="","",IFERROR(VLOOKUP(B22,'Price List'!$B$4:$J$303,7,0),0)) | J22: =IF(H22="","",ROUND(H22*I22/100,2)) | K22: =IF(H22="","",H22+J22)
A23: 9 | C23: =IF(B23="","",IFERROR(VLOOKUP(B23,'Price List'!$B$4:$J$303,2,0),"- not found -")) | D23: =IF(B23="","",IFERROR(VLOOKUP(B23,'Price List'!$B$4:$J$303,3,0),"")) | F23: =IF(B23="","",IF($B$8="Retail",IFERROR(VLOOKUP(B23,'Price List'!$B$4:$J$303,4,0),0),IF($B$8="Trade",IFERROR(VLOOKUP(B23,'Price List'!$B$4:$J$303,5,0),0),IFERROR(VLOOKUP(B23,'Price List'!$B$4:$J$303,6,0),0)))) | G23: 0 | H23: =IF(B23="","",IF(E23="","",ROUND(F23*(1-G23/100)*E23,2))) | I23: =IF(B23="","",IFERROR(VLOOKUP(B23,'Price List'!$B$4:$J$303,7,0),0)) | J23: =IF(H23="","",ROUND(H23*I23/100,2)) | K23: =IF(H23="","",H23+J23)
A24: 10 | C24: =IF(B24="","",IFERROR(VLOOKUP(B24,'Price List'!$B$4:$J$303,2,0),"- not found -")) | D24: =IF(B24="","",IFERROR(VLOOKUP(B24,'Price List'!$B$4:$J$303,3,0),"")) | F24: =IF(B24="","",IF($B$8="Retail",IFERROR(VLOOKUP(B24,'Price List'!$B$4:$J$303,4,0),0),IF($B$8="Trade",IFERROR(VLOOKUP(B24,'Price List'!$B$4:$J$303,5,0),0),IFERROR(VLOOKUP(B24,'Price List'!$B$4:$J$303,6,0),0)))) | G24: 0 | H24: =IF(B24="","",IF(E24="","",ROUND(F24*(1-G24/100)*E24,2))) | I24: =IF(B24="","",IFERROR(VLOOKUP(B24,'Price List'!$B$4:$J$303,7,0),0)) | J24: =IF(H24="","",ROUND(H24*I24/100,2)) | K24: =IF(H24="","",H24+J24)
A25: 11 | C25: =IF(B25="","",IFERROR(VLOOKUP(B25,'Price List'!$B$4:$J$303,2,0),"- not found -")) | D25: =IF(B25="","",IFERROR(VLOOKUP(B25,'Price List'!$B$4:$J$303,3,0),"")) | F25: =IF(B25="","",IF($B$8="Retail",IFERROR(VLOOKUP(B25,'Price List'!$B$4:$J$303,4,0),0),IF($B$8="Trade",IFERROR(VLOOKUP(B25,'Price List'!$B$4:$J$303,5,0),0),IFERROR(VLOOKUP(B25,'Price List'!$B$4:$J$303,6,0),0)))) | G25: 0 | H25: =IF(B25="","",IF(E25="","",ROUND(F25*(1-G25/100)*E25,2))) | I25: =IF(B25="","",IFERROR(VLOOKUP(B25,'Price List'!$B$4:$J$303,7,0),0)) | J25: =IF(H25="","",ROUND(H25*I25/100,2)) | K25: =IF(H25="","",H25+J25)
A26: 12 | C26: =IF(B26="","",IFERROR(VLOOKUP(B26,'Price List'!$B$4:$J$303,2,0),"- not found -")) | D26: =IF(B26="","",IFERROR(VLOOKUP(B26,'Price List'!$B$4:$J$303,3,0),"")) | F26: =IF(B26="","",IF($B$8="Retail",IFERROR(VLOOKUP(B26,'Price List'!$B$4:$J$303,4,0),0),IF($B$8="Trade",IFERROR(VLOOKUP(B26,'Price List'!$B$4:$J$303,5,0),0),IFERROR(VLOOKUP(B26,'Price List'!$B$4:$J$303,6,0),0)))) | G26: 0 | H26: =IF(B26="","",IF(E26="","",ROUND(F26*(1-G26/100)*E26,2))) | I26: =IF(B26="","",IFERROR(VLOOKUP(B26,'Price List'!$B$4:$J$303,7,0),0)) | J26: =IF(H26="","",ROUND(H26*I26/100,2)) | K26: =IF(H26="","",H26+J26)
A27: 13 | C27: =IF(B27="","",IFERROR(VLOOKUP(B27,'Price List'!$B$4:$J$303,2,0),"- not found -")) | D27: =IF(B27="","",IFERROR(VLOOKUP(B27,'Price List'!$B$4:$J$303,3,0),"")) | F27: =IF(B27="","",IF($B$8="Retail",IFERROR(VLOOKUP(B27,'Price List'!$B$4:$J$303,4,0),0),IF($B$8="Trade",IFERROR(VLOOKUP(B27,'Price List'!$B$4:$J$303,5,0),0),IFERROR(VLOOKUP(B27,'Price List'!$B$4:$J$303,6,0),0)))) | G27: 0 | H27: =IF(B27="","",IF(E27="","",ROUND(F27*(1-G27/100)*E27,2))) | I27: =IF(B27="","",IFERROR(VLOOKUP(B27,'Price List'!$B$4:$J$303,7,0),0)) | J27: =IF(H27="","",ROUND(H27*I27/100,2)) | K27: =IF(H27="","",H27+J27)
... A34: 20 | C34: =IF(B34="","",IFERROR(VLOOKUP(B34,'Price List'!$B$4:$J$303,2,0),"- not found -")) | D34: =IF(B34="","",IFERROR(VLOOKUP(B34,'Price List'!$B$4:$J$303,3,0),"")) | F34: =IF(B34="","",IF($B$8="Retail",IFERROR(VLOOKUP(B34,'Price List'!$B$4:$J$303,4,0),0),IF($B$8="Trade",IFERROR(VLOOKUP(B34,'Price List'!$B$4:$J$303,5,0),0),IFERROR(VLOOKUP(B34,'Price List'!$B$4:$J$303,6,0),0)))) | G34: 0 | H34: =IF(B34="","",IF(E34="","",ROUND(F34*(1-G34/100)*E34,2))) | I34: =IF(B34="","",IFERROR(VLOOKUP(B34,'Price List'!$B$4:$J$303,7,0),0)) | J34: =IF(H34="","",ROUND(H34*I34/100,2)) | K34: =IF(H34="","",H34+J34)
A36: Subtotal (excl. GST): | K36: =SUMIF(B15:B34,"<>",H15:H34) -> 18277.88
A37: Overall Discount (from B11): | K37: =-SUMIF(B15:B34,"<>",H15:H34)*B11/100 -> 0
A38: Total GST: | K38: =SUMIF(B15:B34,"<>",J15:J34) -> 913.89
A39: GRAND TOTAL (incl. GST): | K39: =K36+K37+K38 -> 19191.77

Sheet Quote Output
A1: NIKSANG | G1: QUOTATION
A2: Your trusted partner for quality products & services
A4: Quote Number: | C4: ='Quote Builder'!#REF! -> #REF! | F4: BILL TO: | H4: Saravana Granites
A5: Quote Date: | C5: =TEXT('Quote Builder'!B5,"DD-MMM-YYYY") -> 06-Mar-2026 | F5: Email: | H5: ='Quote Builder'!B9 -> 0
A6: Valid Until: | C6: =TEXT('Quote Builder'!B6,"DD-MMM-YYYY") -> 05-Apr-2026 | F6: Phone: | H6: ='Quote Builder'!B10 -> 0
A7: Customer Type: | C7: ='Quote Builder'!B8 -> Retail
A9: # | B9: Product / Service | C9: Category | D9: Unit | E9: Qty | F9: Unit Price | G9: Disc % | H9: Amount | I9: GST % | J9: Total
A10: 1 | B10: ='Quote Builder'!B15 -> black butching panel | C10: ='Quote Builder'!C15 -> Materials | D10: ='Quote Builder'!D15 -> Sft | E10: ='Quote Builder'!E15 -> 100 | F10: =IF('Quote Builder'!B15="","",ROUND('Quote Builder'!F15,2)) -> 182.78 | G10: =IF('Quote Builder'!B15="","",ROUND('Quote Builder'!G15,2)) -> 0 | H10: =IF('Quote Builder'!B15="","",ROUND('Quote Builder'!H15,2)) -> 18277.88 | I10: =IF('Quote Builder'!B15="","",ROUND('Quote Builder'!I15,2)) -> 5 | J10: =IF('Quote Builder'!B15="","",ROUND('Quote Builder'!K15,2)) -> 19191.77
A11: 2 | B11: ='Quote Builder'!B16 -> 0 | C11: ='Quote Builder'!C16 | D11: ='Quote Builder'!D16 | E11: ='Quote Builder'!E16 -> 0 | F11: =IF('Quote Builder'!B16="","",ROUND('Quote Builder'!F16,2)) | G11: =IF('Quote Builder'!B16="","",ROUND('Quote Builder'!G16,2)) | H11: =IF('Quote Builder'!B16="","",ROUND('Quote Builder'!H16,2)) | I11: =IF('Quote Builder'!B16="","",ROUND('Quote Builder'!I16,2)) | J11: =IF('Quote Builder'!B16="","",ROUND('Quote Builder'!K16,2))
A12: 3 | B12: ='Quote Builder'!B17 -> 0 | C12: ='Quote Builder'!C17 | D12: ='Quote Builder'!D17 | E12: ='Quote Builder'!E17 -> 0 | F12: =IF('Quote Builder'!B17="","",ROUND('Quote Builder'!F17,2)) | G12: =IF('Quote Builder'!B17="","",ROUND('Quote Builder'!G17,2)) | H12: =IF('Quote Builder'!B17="","",ROUND('Quote Builder'!H17,2)) | I12: =IF('Quote Builder'!B17="","",ROUND('Quote Builder'!I17,2)) | J12: =IF('Quote Builder'!B17="","",ROUND('Quote Builder'!K17,2))
A13: 4 | B13: ='Quote Builder'!B18 -> 0 | C13: ='Quote Builder'!C18 | D13: ='Quote Builder'!D18 | E13: ='Quote Builder'!E18 -> 0 | F13: =IF('Quote Builder'!B18="","",ROUND('Quote Builder'!F18,2)) | G13: =IF('Quote Builder'!B18="","",ROUND('Quote Builder'!G18,2)) | H13: =IF('Quote Builder'!B18="","",ROUND('Quote Builder'!H18,2)) | I13: =IF('Quote Builder'!B18="","",ROUND('Quote Builder'!I18,2)) | J13: =IF('Quote Builder'!B18="","",ROUND('Quote Builder'!K18,2))
A14: 5 | B14: ='Quote Builder'!B19 -> 0 | C14: ='Quote Builder'!C19 | D14: ='Quote Builder'!D19 | E14: ='Quote Builder'!E19 -> 0 | F14: =IF('Quote Builder'!B19="","",ROUND('Quote Builder'!F19,2)) | G14: =IF('Quote Builder'!B19="","",ROUND('Quote Builder'!G19,2)) | H14: =IF('Quote Builder'!B19="","",ROUND('Quote Builder'!H19,2)) | I14: =IF('Quote Builder'!B19="","",ROUND('Quote Builder'!I19,2)) | J14: =IF('Quote Builder'!B19="","",ROUND('Quote Builder'!K19,2))
A15: 6 | B15: ='Quote Builder'!B20 -> 0 | C15: ='Quote Builder'!C20 | D15: ='Quote Builder'!D20 | E15: ='Quote Builder'!E20 -> 0 | F15: =IF('Quote Builder'!B20="","",ROUND('Quote Builder'!F20,2)) | G15: =IF('Quote Builder'!B20="","",ROUND('Quote Builder'!G20,2)) | H15: =IF('Quote Builder'!B20="","",ROUND('Quote Builder'!H20,2)) | I15: =IF('Quote Builder'!B20="","",ROUND('Quote Builder'!I20,2)) | J15: =IF('Quote Builder'!B20="","",ROUND('Quote Builder'!K20,2))
A16: 7 | B16: ='Quote Builder'!B21 -> 0 | C16: ='Quote Builder'!C21 | D16: ='Quote Builder'!D21 | E16: ='Quote Builder'!E21 -> 0 | F16: =IF('Quote Builder'!B21="","",ROUND('Quote Builder'!F21,2)) | G16: =IF('Quote Builder'!B21="","",ROUND('Quote Builder'!G21,2)) | H16: =IF('Quote Builder'!B21="","",ROUND('Quote Builder'!H21,2)) | I16: =IF('Quote Builder'!B21="","",ROUND('Quote Builder'!I21,2)) | J16: =IF('Quote Builder'!B21="","",ROUND('Quote Builder'!K21,2))
A17: 8 | B17: ='Quote Builder'!B22 -> 0 | C17: ='Quote Builder'!C22 | D17: ='Quote Builder'!D22 | E17: ='Quote Builder'!E22 -> 0 | F17: =IF('Quote Builder'!B22="","",ROUND('Quote Builder'!F22,2)) | G17: =IF('Quote Builder'!B22="","",ROUND('Quote Builder'!G22,2)) | H17: =IF('Quote Builder'!B22="","",ROUND('Quote Builder'!H22,2)) | I17: =IF('Quote Builder'!B22="","",ROUND('Quote Builder'!I22,2)) | J17: =IF('Quote Builder'!B22="","",ROUND('Quote Builder'!K22,2))
A18: 9 | B18: ='Quote Builder'!B23 -> 0 | C18: ='Quote Builder'!C23 | D18: ='Quote Builder'!D23 | E18: ='Quote Builder'!E23 -> 0 | F18: =IF('Quote Builder'!B23="","",ROUND('Quote Builder'!F23,2)) | G18: =IF('Quote Builder'!B23="","",ROUND('Quote Builder'!G23,2)) | H18: =IF('Quote Builder'!B23="","",ROUND('Quote Builder'!H23,2)) | I18: =IF('Quote Builder'!B23="","",ROUND('Quote Builder'!I23,2)) | J18: =IF('Quote Builder'!B23="","",ROUND('Quote Builder'!K23,2))
A19: 10 | B19: ='Quote Builder'!B24 -> 0 | C19: ='Quote Builder'!C24 | D19: ='Quote Builder'!D24 | E19: ='Quote Builder'!E24 -> 0 | F19: =IF('Quote Builder'!B24="","",ROUND('Quote Builder'!F24,2)) | G19: =IF('Quote Builder'!B24="","",ROUND('Quote Builder'!G24,2)) | H19: =IF('Quote Builder'!B24="","",ROUND('Quote Builder'!H24,2)) | I19: =IF('Quote Builder'!B24="","",ROUND('Quote Builder'!I24,2)) | J19: =IF('Quote Builder'!B24="","",ROUND('Quote Builder'!K24,2))
A20: 11 | B20: ='Quote Builder'!B25 -> 0 | C20: ='Quote Builder'!C25 | D20: ='Quote Builder'!D25 | E20: ='Quote Builder'!E25 -> 0 | F20: =IF('Quote Builder'!B25="","",ROUND('Quote Builder'!F25,2)) | G20: =IF('Quote Builder'!B25="","",ROUND('Quote Builder'!G25,2)) | H20: =IF('Quote Builder'!B25="","",ROUND('Quote Builder'!H25,2)) | I20: =IF('Quote Builder'!B25="","",ROUND('Quote Builder'!I25,2)) | J20: =IF('Quote Builder'!B25="","",ROUND('Quote Builder'!K25,2))
A21: 12 | B21: ='Quote Builder'!B26 -> 0 | C21: ='Quote Builder'!C26 | D21: ='Quote Builder'!D26 | E21: ='Quote Builder'!E26 -> 0 | F21: =IF('Quote Builder'!B26="","",ROUND('Quote Builder'!F26,2)) | G21: =IF('Quote Builder'!B26="","",ROUND('Quote Builder'!G26,2)) | H21: =IF('Quote Builder'!B26="","",ROUND('Quote Builder'!H26,2)) | I21: =IF('Quote Builder'!B26="","",ROUND('Quote Builder'!I26,2)) | J21: =IF('Quote Builder'!B26="","",ROUND('Quote Builder'!K26,2))
... A29: 20 | B29: ='Quote Builder'!B34 -> 0 | C29: ='Quote Builder'!C34 | D29: ='Quote Builder'!D34 | E29: ='Quote Builder'!E34 -> 0 | F29: =IF('Quote Builder'!B34="","",ROUND('Quote Builder'!F34,2)) | G29: =IF('Quote Builder'!B34="","",ROUND('Quote Builder'!G34,2)) | H29: =IF('Quote Builder'!B34="","",ROUND('Quote Builder'!H34,2)) | I29: =IF('Quote Builder'!B34="","",ROUND('Quote Builder'!I34,2)) | J29: =IF('Quote Builder'!B34="","",ROUND('Quote Builder'!K34,2))
A31: Subtotal (excl. GST): | J31: =ROUND('Quote Builder'!K36,2) -> 18277.88
A32: Discount: | J32: =ROUND('Quote Builder'!K37,2) -> 0
A33: Total GST: | J33: =ROUND('Quote Builder'!K38,2) -> 913.89
A34: GRAND TOTAL: | J34: =ROUND('Quote Builder'!K39,2) -> 19191.77
A36: TERMS & CONDITIONS
A37: 1. This quotation is valid for 30 days from the date of issue.
A38: 2. Prices are subject to change after the validity period.
A39: 3. 50% advance payment required to confirm the order.
A40: 4. Delivery timeline will be confirmed upon order confirmation.
A41: 5. GST will be charged as per government regulations.
A42: 6. Any disputes are subject to local jurisdiction.
A44: Thank you for your business! | NIKSANG | For queries, contact us at: [your email/phone]

Sheet Settings
A1: NIKSANG — SETTINGS
A3: Company Name: | B3: Niksang | C3: ← You can edit this
A4: GST Rate 1 (%): | B4: 5 | C4: ← You can edit this
A5: GST Rate 2 (%): | B5: 12 | C5: ← You can edit this
A6: GST Rate 3 (%): | B6: 18 | C6: ← You can edit this
A7: Tier 1 Name: | B7: Retail | C7: ← You can edit this
A8: Tier 2 Name: | B8: Trade | C8: ← You can edit this
A9: Tier 3 Name: | B9: Wholesale | C9: ← You can edit this
A10: Default Validity (days): | B10: 30 | C10: ← You can edit this
A11: Max Products in Price List: | B11: 300 | C11: ← You can edit this
A12: Terms Line 1: | B12: Payment due within 30 days of invoice. | C12: ← You can edit this
A13: Terms Line 2: | B13: All prices are in local currency. | C13: ← You can edit this
